Workbook

Sheet README
A1: Main comparison tables - 8STD (standard-phase template + DQN) vs GS-ENUM (enumerated phase sets + FRAP) - 2026-09-30
A3: Sheets: Overview | 1x1 | 1x3 | Dublin 02h | Dublin 11h | Dublin 18h. Each block: 5 stopped-time rows + ordering gate + 5 stop-event rows + ordering gate.
A4: Means and s.d. are measured data (copied from the json behind each PNG); relative differences, ordering gates, type-swap statistics and per-seed recomputations are formulas. Green cell = the better (lower) arm in that row.
A5: Protocol A (best checkpoint x evaluation seeds): each arm's best.pth (best sliding mean of 3 evaluations during training) is re-evaluated once per seed (123-132); training-collector metrics, 5 s sampling, per visit; 'GS wins' = number of seeds where GS is better (paired by seed).
A6: Protocol B (tail-40 evaluations): the 40 evaluations at episodes 605-800 (every 5) during training, evaluation seed 123 fixed - 40 different policies on one seed. Only the Dublin 11h tail-40 block uses this protocol (same data as the 11h block of main_comparison_8std_vs_frap_2026-09-22_en.png).
A7: A and B are not directly comparable: A measures the robustness of one fixed policy to traffic randomness; B measures late-training policy fluctuation.
A8: Anomaly exclusion only by symmetric, stated rules (any junction with all-class stopped time above the threshold in either arm -> the seed is removed from both arms). Each block title states whether the rule hit.
A9: J(531) = per-class per-visit metric weighted 5/3/1 (ambulance/bus/car) by each scenario's traffic shares (see plotting scripts).
A10: Ambulance sample: Dublin 02h has 2 ambulances per evaluation, 11h has 4, 18h has 1 (probe route); grids 1x1/1x3 have many more. Do not cite the Dublin ambulance means alone.
A11: Dublin 11h: the primary block is the USER-SELECTED protocol - seeds 128 and 132 removed from both arms, because in those two seeds the 8STD ambulance amb_0 was caught for 45 s / 90 s at junction 389281 by the Aungier Street right-turn queue spilling back from the unsignalised yield junction (an exogenous bottleneck outside the control set). The full 10-seed result is kept as a reference block; both appear in the Overview.
A12: Dublin 18h: PRIMARY block has three arms - 8STD (exp298 ep200), GS (exp300 ep145: split-slot net only) and GS-2 (exp301 ep95: exp300 + since-green observation + log-scale waiting + pressure-anchored phase score + TD-target floor -50); computed from the raw per-seed collector json with the same formulas as the PNG tables. Reference blocks below it: two-arm rerouted v2 (177 cars/h leave at the end of the Aungier approach instead of turning into Peter's Row; GS uses the split-slot enumerated net), best checkpoints exp298 ep200 (8STD, training stopped at ep253) vs exp300 ep145 (GS, training still running) - a snapshot, not a final result. A USER-SELECTED 5-seed block (seeds with zero ambulance stops in both arms) and the original-scenario blocks (exp289/290, 7 of 10 seeds anomalous by the >100 s rule) are kept as reference.
A13: Source files and generator: experiments/tools/figures/build_main_comparison_xlsx_2026-09-30.py; json paths are on line 2 of each sheet.

Sheet Overview
A1: Overview: all-class stopped time / visit and J(531) per block (formulas referencing the scenario sheets)
A2: Scenario / block | B2: Protocol | C2: 8STD all-class stopped time / visit (s) | D2: GS-ENUM all-class stopped time / visit (s) | E2: Rel. diff | F2: 8STD J(531) | G2: GS-ENUM J(531) | H2: J rel. diff | I2: GS wins (J) | J2: Ordering gate 8STD (stopped time) | K2: Ordering gate GS (stopped time)
A3: 1x1: 1x1, best checkpoints (8STD: exp274 ep1325, GS-ENUM: exp263 ep1370), 10 seeds; anomaly rule (junction > 50 s): no hits | B3: A | C3: =1x1!B9 -> 30.86629 | D3: =1x1!D9 -> 33.394747 | E3: =IF(C3=0,"",D3/C3-1) -> 0.081916462 | F3: =1x1!B10 -> 31.809305 | G3: =1x1!D10 -> 34.407895 | H3: =IF(F3=0,"",G3/F3-1) -> 0.081692756 | I3: =1x1!G10 -> 1/10 | J3: =1x1!B11 -> pass | K3: =1x1!D11 -> pass
A4: 1x1: 1x1, best checkpoints, excl. Tukey-outlier seed(s) 128 (1.5 IQR, all-class stopped time / visit, either arm), n = 9 | B4: A | C4: =1x1!B24 -> 30.394958 | D4: =1x1!D24 -> 33.834928 | E4: =IF(C4=0,"",D4/C4-1) -> 0.11317569 | F4: =1x1!B25 -> 31.32184 | G4: =1x1!D25 -> 34.851823 | H4: =IF(F4=0,"",G4/F4-1) -> 0.11270037 | I4: =1x1!G25 -> 0/9 | J4: =1x1!B26 -> pass | K4: =1x1!D26 -> pass
A5: 1x3: 1x3, best checkpoints (8STD: exp275 ep1785, GS-ENUM: exp265 ep580), 10 seeds; anomaly rule (junction > 50 s): no hits | B5: A | C5: =1x3!B9 -> 23.753603 | D5: =1x3!D9 -> 27.535834 | E5: =IF(C5=0,"",D5/C5-1) -> 0.15922766 | F5: =1x3!B10 -> 24.792079 | G5: =1x3!D10 -> 28.890537 | H5: =IF(F5=0,"",G5/F5-1) -> 0.16531317 | I5: =1x3!G10 -> 0/10 | J5: =1x3!B11 -> pass | K5: =1x3!D11 -> pass
A6: Dublin 02h: Dublin 02:00, ambulance probe route, best checkpoints (8STD: exp287 ep770, GS-ENUM: exp288 ep760), 10 evaluation seeds | B6: A | C6: ='Dublin 02h'!B9 -> 0.75991443 | D6: ='Dublin 02h'!D9 -> 0.65731485 | E6: =IF(C6=0,"",D6/C6-1) -> -0.13501466 | F6: ='Dublin 02h'!B10 -> 0.77037753 | G6: ='Dublin 02h'!D10 -> 0.66641035 | H6: =IF(F6=0,"",G6/F6-1) -> -0.13495615 | I6: ='Dublin 02h'!G10 -> 9/10 | J6: ='Dublin 02h'!B11 -> pass | K6: ='Dublin 02h'!D11 -> pass
A7: Dublin 11h: Dublin 11:00, best checkpoints x 8 seeds, seeds 128 & 132 removed (8STD: exp208 ep240, GS-ENUM: exp211 ep215) [USER-SELECTED] | B7: A | C7: ='Dublin 11h'!B9 -> 2.6792187 | D7: ='Dublin 11h'!D9 -> 1.9546752 | E7: =IF(C7=0,"",D7/C7-1) -> -0.27043091 | F7: ='Dublin 11h'!B10 -> 2.7902746 | G7: ='Dublin 11h'!D10 -> 2.0547157 | H7: =IF(F7=0,"",G7/F7-1) -> -0.26361523 | I7: ='Dublin 11h'!G10 -> 8/8 | J7: ='Dublin 11h'!B11 -> pass | K7: ='Dublin 11h'!D11 -> pass
A8: Dublin 11h: Dublin 11:00, best checkpoints x 10 seeds, all seeds (8STD: exp208 ep240, GS-ENUM: exp211 ep215) [reference] | B8: A | C8: ='Dublin 11h'!B43 -> 2.6578129 | D8: ='Dublin 11h'!D43 -> 1.9288925 | E8: =IF(C8=0,"",D8/C8-1) -> -0.27425573 | F8: ='Dublin 11h'!B44 -> 2.7695931 | G8: ='Dublin 11h'!D44 -> 2.0296419 | H8: =IF(F8=0,"",G8/F8-1) -> -0.26716967 | I8: ='Dublin 11h'!G44 -> 10/10 | J8: ='Dublin 11h'!B45 -> pass (tol. 5 s) | K8: ='Dublin 11h'!D45 -> pass
A9: Dublin 11h: Dublin 11:00 tail-40 [Protocol B] | B9: B | C9: ='Dublin 11h'!B59 -> 4.75 | D9: ='Dublin 11h'!D59 -> 2.38 | E9: =IF(C9=0,"",D9/C9-1) -> -0.49894737 | F9: ='Dublin 11h'!B60 -> 4.89 | G9: ='Dublin 11h'!D60 -> 2.48 | H9: =IF(F9=0,"",G9/F9-1) -> -0.49284254 | I9: ='Dublin 11h'!G60 -> 40/40 | J9: ='Dublin 11h'!B61 -> pass | K9: ='Dublin 11h'!D61 -> pass
A10: Dublin 18h: Dublin 18:00, rerouted scenario v2, best checkpoints x 10 seeds, two arms (8STD: exp298 ep200, GS-ENUM: exp300 ep145); anomaly rule (>100 s): no hits [reference: same data as the PNG] | B10: A | C10: ='Dublin 18h'!B49 -> 3.6038884 | D10: ='Dublin 18h'!D49 -> 5.6830803 | E10: =IF(C10=0,"",D10/C10-1) -> 0.57693015 | F10: ='Dublin 18h'!B50 -> 3.7211636 | G10: ='Dublin 18h'!D50 -> 5.8187598 | H10: =IF(F10=0,"",G10/F10-1) -> 0.56369365 | I10: ='Dublin 18h'!G50 -> 0/10 | J10: ='Dublin 18h'!B51 -> pass | K10: ='Dublin 18h'!D51 -> pass (tol. 5 s)
A11: Dublin 18h: Dublin 18:00, rerouted scenario v2, 5 seeds with zero ambulance stops in both arms (123, 126, 128, 131, 132) [USER-SELECTED] | B11: A | C11: ='Dublin 18h'!B83 -> 3.570581 | D11: ='Dublin 18h'!D83 -> 5.6984722 | E11: =IF(C11=0,"",D11/C11-1) -> 0.59595094 | F11: ='Dublin 18h'!B84 -> 3.6864402 | G11: ='Dublin 18h'!D84 -> 5.8267039 | H11: =IF(F11=0,"",G11/F11-1) -> 0.58057734 | I11: ='Dublin 18h'!G84 -> 0/5 | J11: ='Dublin 18h'!B85 -> pass | K11: ='Dublin 18h'!D85 -> pass
A12: Dublin 18h: Dublin 18:00, ORIGINAL scenario, best checkpoints x 10 seeds (8STD: exp289 ep270, GS-ENUM: exp290 ep75) [reference] | B12: A | C12: ='Dublin 18h'!B102 -> 16.202807 | D12: ='Dublin 18h'!D102 -> 16.550202 | E12: =IF(C12=0,"",D12/C12-1) -> 0.021440399 | F12: ='Dublin 18h'!B103 -> 17.001119 | G12: ='Dublin 18h'!D103 -> 17.265184 | H12: =IF(F12=0,"",G12/F12-1) -> 0.015532215 | I12: ='Dublin 18h'!G103 -> 4/10 | J12: ='Dublin 18h'!B104 -> fail | K12: ='Dublin 18h'!D104 -> fail
A13: Dublin 18h: Dublin 18:00, ORIGINAL scenario, excl. 7 anomalous seeds (any junction > 100 s in either arm: 124, 125, 127, 128, 130, 131, 132), 3 seeds [reference] | B13: A | C13: ='Dublin 18h'!B117 -> 15.349426 | D13: ='Dublin 18h'!D117 -> 13.297637 | E13: =IF(C13=0,"",D13/C13-1) -> -0.13367206 | F13: ='Dublin 18h'!B118 -> 16.078704 | G13: ='Dublin 18h'!D118 -> 13.759763 | H13: =IF(F13=0,"",G13/F13-1) -> -0.14422436 | I13: ='Dublin 18h'!G118 -> 2/3 | J13: ='Dublin 18h'!B119 -> pass | K13: ='Dublin 18h'!D119 -> pass
A15: Dublin 18h three-arm block (8STD | GS exp300 | GS-2 exp301): all-class stopped time / visit and J(531)
A16: Block | B16: Protocol | C16: 8STD all | D16: GS (exp300) all | E16: GS-2 (exp301) all | F16: GS vs 8STD | G16: GS-2 vs 8STD | H16: 8STD J | I16: GS J | J16: GS-2 J | K16: GS wins (J) | L16: GS-2 wins (J)
A17: Dublin 18:00 rerouted v2, three arms, 10 seeds [PRIMARY] | B17: A | C17: ='Dublin 18h'!B9 -> 3.6038884 | D17: ='Dublin 18h'!D9 -> 5.6830803 | E17: ='Dublin 18h'!F9 -> 3.0521644 | F17: =IF(C17=0,"",D17/C17-1) -> 0.57693015 | G17: =IF(C17=0,"",E17/C17-1) -> -0.1530913 | H17: ='Dublin 18h'!B10 -> 3.7211636 | I17: ='Dublin 18h'!D10 -> 5.8187598 | J17: ='Dublin 18h'!F10 -> 3.1888242 | K17: ='Dublin 18h'!K10 -> 0/10 | L17: ='Dublin 18h'!L10 -> 10/10

Sheet 1x1
A1: 1x1: best checkpoints x 10 evaluation seeds (123, 124, 125, 126, 127, 128, 129, 130, 131, 132); Protocol A
A2: Source: experiments/analysis/figures/main_comparison_1x1_best10seeds_2026-09-30_en.json (same data as the PNG of that name); anomalous seeds (symmetric rule): none; Tukey outlier seeds: [128]
A4: 1x1, best checkpoints (8STD: exp274 ep1325, GS-ENUM: exp263 ep1370), 10 seeds; anomaly rule (junction > 50 s): no hits
A5: Metric | B5: 8STD mean | C5: 8STD s.d. | D5: GS-ENUM mean | E5: GS-ENUM s.d. | F5: Rel. diff (GS-8STD)/8STD | G5: GS wins / paired | H5: Notes
A6: Stopped time / visit (s) - car | B6: 32.231806 | C6: 1.6769767 | D6: 34.883423 | E6: 2.3182102 | F6: =IF(B6=0,"",D6/B6-1) -> 0.082267102
A7: Stopped time / visit (s) - bus | B7: 6.7625 | C7: 0.88467861 | D7: 7.15 | E7: 0.5667892 | F7: =IF(B7=0,"",D7/B7-1) -> 0.057301294
A8: Stopped time / visit (s) - ambulance | B8: 4.25 | C8: 3.2585358 | D8: 4.4166667 | E8: 3.25 | F8: =IF(B8=0,"",D8/B8-1) -> 0.039215686 | H8: Few ambulances per evaluation in Dublin (02h: 2, 11h: 4, 18h: 1); do not cite the mean alone
A9: Stopped time / visit (s) - all | B9: 30.86629 | C9: 1.5909816 | D9: 33.394747 | E9: 2.205688 | F9: =IF(B9=0,"",D9/B9-1) -> 0.081916462
A10: J(531) weighted cost (per visit) | B10: 31.809305 | C10: 1.6482475 | D10: 34.407895 | E10: 2.2426986 | F10: =IF(B10=0,"",D10/B10-1) -> 0.081692756 | G10: 1/10
A11: Ordering gate (stopped time): amb <= bus <= car | B11: =IF(AND(B8<=B7,B7<=B6),"pass",IF(AND(B8-B7<=5,B7-B6<=5),"pass (tol. 5 s)","fail")) -> pass | D11: =IF(AND(D8<=D7,D7<=D6),"pass",IF(AND(D8-D7<=5,D7-D6<=5),"pass (tol. 5 s)","fail")) -> pass | H11: tol. 5 s = tolerance of one 5 s sampling quantum
A12: Stop events / visit - car | B12: 1.1278976 | C12: 0.037121736 | D12: 1.2309973 | E12: 0.058952675 | F12: =IF(B12=0,"",D12/B12-1) -> 0.09140877
A13: Stop events / visit - bus | B13: 0.8325 | C13: 0.085183625 | D13: 0.77 | E13: 0.06 | F13: =IF(B13=0,"",D13/B13-1) -> -0.075075075
A14: Stop events / visit - ambulance | B14: 0.53333333 | C14: 0.42031734 | D14: 0.53333333 | E14: 0.3929942 | F14: =IF(B14=0,"",D14/B14-1) -> 0 | H14: Few ambulances per evaluation in Dublin (02h: 2, 11h: 4, 18h: 1); do not cite the mean alone
A15: Stop events / visit - all | B15: 1.1116299 | C15: 0.037762355 | D15: 1.2056587 | E15: 0.057235023 | F15: =IF(B15=0,"",D15/B15-1) -> 0.08458642
A16: J(531) weighted stop events (per visit) | B16: 1.175372 | C16: 0.041050969 | D16: 1.2686757 | E16: 0.05983822 | F16: =IF(B16=0,"",D16/B16-1) -> 0.079382307 | G16: 1/10
A17: Ordering gate (stop events): amb <= bus <= car | B17: =IF(AND(B14<=B13,B13<=B12),"pass",IF(AND(B14-B13<=0.5,B13-B12<=0.5),"pass (tol.)","fail")) -> pass | D17: =IF(AND(D14<=D13,D13<=D12),"pass",IF(AND(D14-D13<=0.5,D13-D12<=0.5),"pass (tol.)","fail")) -> pass
A19: 1x1, best checkpoints, excl. Tukey-outlier seed(s) 128 (1.5 IQR, all-class stopped time / visit, either arm), n = 9
A20: Metric | B20: 8STD mean | C20: 8STD s.d. | D20: GS-ENUM mean | E20: GS-ENUM s.d. | F20: Rel. diff (GS-8STD)/8STD | G20: GS wins / paired | H20: Notes
A21: Stopped time / visit (s) - car | B21: 31.730308 | C21: 0.78084957 | D21: 35.345163 | E21: 1.9593831 | F21: =IF(B21=0,"",D21/B21-1) -> 0.11392435
A22: Stopped time / visit (s) - bus | B22: 6.75 | C22: 0.93169499 | D22: 7.1388889 | E22: 0.59641418 | F22: =IF(B22=0,"",D22/B22-1) -> 0.057613169
A23: Stopped time / visit (s) - ambulance | B23: 3.9814815 | C23: 3.3281853 | D23: 4.3518519 | E23: 3.4196639 | F23: =IF(B23=0,"",D23/B23-1) -> 0.093023256 | H23: Few ambulances per evaluation in Dublin (02h: 2, 11h: 4, 18h: 1); do not cite the mean alone
A24: Stopped time / visit (s) - all | B24: 30.394958 | C24: 0.76871857 | D24: 33.834928 | E24: 1.8622651 | F24: =IF(B24=0,"",D24/B24-1) -> 0.11317569
A25: J(531) weighted cost (per visit) | B25: 31.32184 | C25: 0.80147174 | D25: 34.851823 | E25: 1.9020594 | F25: =IF(B25=0,"",D25/B25-1) -> 0.11270037 | G25: 0/9
A26: Ordering gate (stopped time): amb <= bus <= car | B26: =IF(AND(B23<=B22,B22<=B21),"pass",IF(AND(B23-B22<=5,B22-B21<=5),"pass (tol. 5 s)","fail")) -> pass | D26: =IF(AND(D23<=D22,D22<=D21),"pass",IF(AND(D23-D22<=5,D22-D21<=5),"pass (tol. 5 s)","fail")) -> pass | H26: tol. 5 s = tolerance of one 5 s sampling quantum
A27: Stop events / visit - car | B27: 1.1214435 | C27: 0.033385508 | D27: 1.2424379 | E27: 0.050524384 | F27: =IF(B27=0,"",D27/B27-1) -> 0.10789157
A28: Stop events / visit - bus | B28: 0.83055556 | C28: 0.089580642 | D28: 0.775 | E28: 0.061237244 | F28: =IF(B28=0,"",D28/B28-1) -> -0.066889632
A29: Stop events / visit - ambulance | B29: 0.48148148 | C29: 0.41159464 | D29: 0.51851852 | E29: 0.41159464 | F29: =IF(B29=0,"",D29/B29-1) -> 0.076923077 | H29: Few ambulances per evaluation in Dublin (02h: 2, 11h: 4, 18h: 1); do not cite the mean alone
A30: Stop events / visit - all | B30: 1.1053496 | C30: 0.034496578 | D30: 1.2167616 | E30: 0.049062048 | F30: =IF(B30=0,"",D30/B30-1) -> 0.10079349
A31: J(531) weighted stop events (per visit) | B31: 1.1685106 | C31: 0.037438475 | D31: 1.2800849 | E31: 0.051737401 | F31: =IF(B31=0,"",D31/B31-1) -> 0.095484219 | G31: 0/9
A32: Ordering gate (stop events): amb <= bus <= car | B32: =IF(AND(B29<=B28,B28<=B27),"pass",IF(AND(B29-B28<=0.5,B28-B27<=0.5),"pass (tol.)","fail")) -> pass | D32: =IF(AND(D29<=D28,D28<=D27),"pass",IF(AND(D29-D28<=0.5,D28-D27<=0.5),"pass (tol.)","fail")) -> pass
A34: 1x1: per-seed raw values, mean / s.d. recomputed by formula
A35: Arm / class / metric | B35: seed 123 | C35: seed 124 | D35: seed 125 | E35: seed 126 | F35: seed 127 | G35: seed 128 | H35: seed 129 | I35: seed 130 | J35: seed 131 | K35: seed 132 | L35: Mean | M35: S.d.
A36: 8STD - car - stopped time / visit (s) | B36: 31.75876 | C36: 30.444744 | D36: 31.057951 | E36: 32.297844 | F36: 31.448787 | G36: 36.745283 | H36: 32.513477 | I36: 32.648248 | J36: 32.574124 | K36: 30.828841 | L36: =AVERAGE(B36:K36) -> 32.231806 | M36: =STDEV(B36:K36) -> 1.7676886
A37: 8STD - car - stop events / visit | B37: 1.0633423 | C37: 1.0983827 | D37: 1.1361186 | E37: 1.1495957 | F37: 1.0929919 | G37: 1.1859838 | H37: 1.1334232 | I37: 1.1684636 | J37: 1.0943396 | K37: 1.1563342 | L37: =AVERAGE(B37:K37) -> 1.1278976 | M37: =STDEV(B37:K37) -> 0.039129745
A38: 8STD - bus - stopped time / visit (s) | B38: 5.5 | C38: 5.625 | D38: 5.75 | E38: 8.375 | F38: 6.75 | G38: 6.875 | H38: 7.5 | I38: 6.75 | J38: 6.875 | K38: 7.625 | L38: =AVERAGE(B38:K38) -> 6.7625 | M38: =STDEV(B38:K38) -> 0.93253314
A39: 8STD - bus - stop events / visit | B39: 0.675 | C39: 0.75 | D39: 0.825 | E39: 1 | F39: 0.825 | G39: 0.85 | H39: 0.775 | I39: 0.85 | J39: 0.925 | K39: 0.85 | L39: =AVERAGE(B39:K39) -> 0.8325 | M39: =STDEV(B39:K39) -> 0.089791425
A40: 8STD - ambulance - stopped time / visit (s) | B40: 5 | C40: 3.3333333 | D40: 5 | E40: 0 | F40: 0 | G40: 6.6666667 | H40: 7.5 | I40: 0 | J40: 10 | K40: 5 | L40: =AVERAGE(B40:K40) -> 4.25 | M40: =STDEV(B40:K40) -> 3.4347983
A41: 8STD - ambulance - stop events / visit | B41: 0.5 | C41: 0.33333333 | D41: 0.5 | E41: 0 | F41: 0 | G41: 1 | H41: 1 | I41: 0 | J41: 1 | K41: 1 | L41: =AVERAGE(B41:K41) -> 0.53333333 | M41: =STDEV(B41:K41) -> 0.44305338
A42: 8STD - all - stopped time / visit (s) | B42: 30.350765 | C42: 29.076433 | D42: 29.700255 | E42: 31.034483 | F42: 30.146871 | G42: 35.10828 | H42: 31.173469 | I42: 31.283525 | J42: 31.178344 | K42: 29.610473 | L42: =AVERAGE(B42:K42) -> 30.86629 | M42: =STDEV(B42:K42) -> 1.6770418
A43: 8STD - all - stop events / visit | B43: 1.0420918 | C43: 1.077707 | D43: 1.1186224 | E43: 1.1404853 | F43: 1.0779055 | G43: 1.1681529 | H43: 1.1147959 | I43: 1.1507024 | J43: 1.0853503 | K43: 1.1404853 | L43: =AVERAGE(B43:K43) -> 1.1116299 | M43: =STDEV(B43:K43) -> 0.039805017
...

Sheet 1x3
A1: 1x3: best checkpoints x 10 evaluation seeds (123, 124, 125, 126, 127, 128, 129, 130, 131, 132); Protocol A
A2: Source: experiments/analysis/figures/main_comparison_1x3_best10seeds_2026-09-30_en.json (same data as the PNG of that name); anomalous seeds (symmetric rule): none; Tukey outlier seeds: none
A4: 1x3, best checkpoints (8STD: exp275 ep1785, GS-ENUM: exp265 ep580), 10 seeds; anomaly rule (junction > 50 s): no hits
A5: Metric | B5: 8STD mean | C5: 8STD s.d. | D5: GS-ENUM mean | E5: GS-ENUM s.d. | F5: Rel. diff (GS-8STD)/8STD | G5: GS wins / paired | H5: Notes
A6: Stopped time / visit (s) - car | B6: 25.351589 | C6: 1.0868683 | D6: 29.212451 | E6: 1.1114029 | F6: =IF(B6=0,"",D6/B6-1) -> 0.15229268
A7: Stopped time / visit (s) - bus | B7: 4.7041667 | C7: 0.54116964 | D7: 7.5458333 | E7: 0.6125 | F7: =IF(B7=0,"",D7/B7-1) -> 0.6040744
A8: Stopped time / visit (s) - ambulance | B8: 1.7460317 | C8: 1.2747919 | D8: 4.8809524 | E8: 1.5703459 | F8: =IF(B8=0,"",D8/B8-1) -> 1.7954545 | H8: Few ambulances per evaluation in Dublin (02h: 2, 11h: 4, 18h: 1); do not cite the mean alone
A9: Stopped time / visit (s) - all | B9: 23.753603 | C9: 1.0292723 | D9: 27.535834 | E9: 1.0540016 | F9: =IF(B9=0,"",D9/B9-1) -> 0.15922766
A10: J(531) weighted cost (per visit) | B10: 24.792079 | C10: 1.0820955 | D10: 28.890537 | E10: 1.1200837 | F10: =IF(B10=0,"",D10/B10-1) -> 0.16531317 | G10: 0/10
A11: Ordering gate (stopped time): amb <= bus <= car | B11: =IF(AND(B8<=B7,B7<=B6),"pass",IF(AND(B8-B7<=5,B7-B6<=5),"pass (tol. 5 s)","fail")) -> pass | D11: =IF(AND(D8<=D7,D7<=D6),"pass",IF(AND(D8-D7<=5,D7-D6<=5),"pass (tol. 5 s)","fail")) -> pass | H11: tol. 5 s = tolerance of one 5 s sampling quantum
A12: Stop events / visit - car | B12: 1.0216194 | C12: 0.024998012 | D12: 1.0968901 | E12: 0.02351996 | F12: =IF(B12=0,"",D12/B12-1) -> 0.073677802
A13: Stop events / visit - bus | B13: 0.62416667 | C13: 0.061514452 | D13: 0.815 | E13: 0.035707142 | F13: =IF(B13=0,"",D13/B13-1) -> 0.30574099
A14: Stop events / visit - ambulance | B14: 0.28571429 | C14: 0.21295885 | D14: 0.58730159 | E14: 0.22587698 | F14: =IF(B14=0,"",D14/B14-1) -> 1.0555556 | H14: Few ambulances per evaluation in Dublin (02h: 2, 11h: 4, 18h: 1); do not cite the mean alone
A15: Stop events / visit - all | B15: 0.99063703 | C15: 0.026248075 | D15: 1.0749495 | E15: 0.022258787 | F15: =IF(B15=0,"",D15/B15-1) -> 0.085109384
A16: J(531) weighted stop events (per visit) | B16: 1.0645635 | C16: 0.030442241 | D16: 1.1651178 | E16: 0.023410399 | F16: =IF(B16=0,"",D16/B16-1) -> 0.094455959 | G16: 1/10
A17: Ordering gate (stop events): amb <= bus <= car | B17: =IF(AND(B14<=B13,B13<=B12),"pass",IF(AND(B14-B13<=0.5,B13-B12<=0.5),"pass (tol.)","fail")) -> pass | D17: =IF(AND(D14<=D13,D13<=D12),"pass",IF(AND(D14-D13<=0.5,D13-D12<=0.5),"pass (tol.)","fail")) -> pass
A19: 1x3: per-seed raw values, mean / s.d. recomputed by formula
A20: Arm / class / metric | B20: seed 123 | C20: seed 124 | D20: seed 125 | E20: seed 126 | F20: seed 127 | G20: seed 128 | H20: seed 129 | I20: seed 130 | J20: seed 131 | K20: seed 132 | L20: Mean | M20: S.d.
A21: 8STD - car - stopped time / visit (s) | B21: 24.487445 | C21: 24.463257 | D21: 27.088804 | E21: 26.476618 | F21: 25.451509 | G21: 24.928588 | H21: 26.499079 | I21: 24.120018 | J21: 23.833218 | K21: 26.167358 | L21: =AVERAGE(B21:K21) -> 25.351589 | M21: =STDEV(B21:K21) -> 1.1456598
A22: 8STD - car - stop events / visit | B22: 1.0071412 | C22: 1.0214236 | D22: 1.0793596 | E22: 1.0239576 | F22: 1.0119788 | G22: 1.0085234 | H22: 1.0425017 | I22: 0.98836674 | J22: 0.99596867 | K22: 1.036973 | L22: =AVERAGE(B22:K22) -> 1.0216194 | M22: =STDEV(B22:K22) -> 0.026350218
A23: 8STD - bus - stopped time / visit (s) | B23: 4.4583333 | C23: 4.8333333 | D23: 5.4583333 | E23: 4.9583333 | F23: 4.375 | G23: 5.5 | H23: 5.0416667 | I23: 3.625 | J23: 4.3333333 | K23: 4.4583333 | L23: =AVERAGE(B23:K23) -> 4.7041667 | M23: =STDEV(B23:K23) -> 0.57044289
A24: 8STD - bus - stop events / visit | B24: 0.575 | C24: 0.66666667 | D24: 0.65 | E24: 0.69166667 | F24: 0.60833333 | G24: 0.675 | H24: 0.69166667 | I24: 0.5 | J24: 0.55 | K24: 0.63333333 | L24: =AVERAGE(B24:K24) -> 0.62416667 | M24: =STDEV(B24:K24) -> 0.064841926
A25: 8STD - ambulance - stopped time / visit (s) | B25: 0 | D25: 1.6666667 | F25: 3.3333333 | G25: 1.6666667 | H25: 3.3333333 | J25: 2.2222222 | K25: 0 | L25: =AVERAGE(B25:K25) -> 1.7460317 | M25: =STDEV(B25:K25) -> 1.3769327
A26: 8STD - ambulance - stop events / visit | B26: 0 | D26: 0.33333333 | F26: 0.33333333 | G26: 0.33333333 | H26: 0.66666667 | J26: 0.33333333 | K26: 0 | L26: =AVERAGE(B26:K26) -> 0.28571429 | M26: =STDEV(B26:K26) -> 0.23002185
A27: 8STD - all - stopped time / visit (s) | B27: 22.924368 | C27: 22.960009 | D27: 25.402061 | E27: 24.82876 | F27: 23.824405 | G27: 23.413002 | H27: 24.842156 | I27: 22.550521 | J27: 22.301486 | K27: 24.489264 | L27: =AVERAGE(B27:K27) -> 23.753603 | M27: =STDEV(B27:K27) -> 1.0849482
A28: 8STD - all - stop events / visit | B28: 0.97280646 | C28: 0.99425654 | D28: 1.0455704 | E28: 0.99851096 | F28: 0.98065476 | G28: 0.98215424 | H28: 1.0154124 | I28: 0.95096788 | J28: 0.96061571 | K28: 1.0054209 | L28: =AVERAGE(B28:K28) -> 0.99063703 | M28: =STDEV(B28:K28) -> 0.027667901
A29: GS - car - stopped time / visit (s) | B29: 29.780005 | C29: 29.714352 | D29: 26.946556 | E29: 28.55736 | F29: 29.493204 | G29: 29.069915 | H29: 28.153651 | I29: 28.915572 | J29: 31.060815 | K29: 30.43308 | L29: =AVERAGE(B29:K29) -> 29.212451 | M29: =STDEV(B29:K29) -> 1.1715215
A30: GS - car - stop events / visit | B30: 1.1116102 | C30: 1.1081548 | D30: 1.0444598 | E30: 1.0985948 | F30: 1.0992859 | G30: 1.0954849 | H30: 1.0638102 | I30: 1.1230131 | J30: 1.1217461 | K30: 1.1027413 | L30: =AVERAGE(B30:K30) -> 1.0968901 | M30: =STDEV(B30:K30) -> 0.024792215
A31: GS - bus - stopped time / visit (s) | B31: 8.5416667 | C31: 7.8333333 | D31: 6.9583333 | E31: 6.5833333 | F31: 7.75 | G31: 7.375 | H31: 7.625 | I31: 6.6666667 | J31: 8.1666667 | K31: 7.9583333 | L31: =AVERAGE(B31:K31) -> 7.5458333 | M31: =STDEV(B31:K31) -> 0.64563169
A32: GS - bus - stop events / visit | B32: 0.88333333 | C32: 0.85833333 | D32: 0.80833333 | E32: 0.75 | F32: 0.83333333 | G32: 0.825 | H32: 0.8 | I32: 0.8 | J32: 0.78333333 | K32: 0.80833333 | L32: =AVERAGE(B32:K32) -> 0.815 | M32: =STDEV(B32:K32) -> 0.037638633
A33: GS - ambulance - stopped time / visit (s) | B33: 6.6666667 | D33: 5 | F33: 1.6666667 | G33: 4.1666667 | H33: 6.6666667 | J33: 5 | K33: 5 | L33: =AVERAGE(B33:K33) -> 4.8809524 | M33: =STDEV(B33:K33) -> 1.6961675
A34: GS - ambulance - stop events / visit | B34: 0.66666667 | D34: 0.5 | F34: 0.33333333 | G34: 0.5 | H34: 1 | J34: 0.77777778 | K34: 0.33333333 | L34: =AVERAGE(B34:K34) -> 0.58730159 | M34: =STDEV(B34:K34) -> 0.24397502
A35: GS - all - stopped time / visit (s) | B35: 28.126195 | C35: 28.038715 | D35: 25.389845 | E35: 26.874601 | F35: 27.811437 | G35: 27.378904 | H35: 26.568878 | I35: 27.211763 | J35: 29.261146 | K35: 28.696854 | L35: =AVERAGE(B35:K35) -> 27.535834 | M35: =STDEV(B35:K35) -> 1.1110153
A36: GS - all - stop events / visit | B36: 1.093584 | C36: 1.0890236 | D36: 1.0257064 | E36: 1.0718996 | F36: 1.0784439 | G36: 1.0740387 | H36: 1.0435799 | I36: 1.098277 | J36: 1.0952229 | K36: 1.0797194 | L36: =AVERAGE(B36:K36) -> 1.0749495 | M36: =STDEV(B36:K36) -> 0.023462821

Sheet Dublin 02h
A1: Dublin 02h: best checkpoints x 10 evaluation seeds (123, 124, 125, 126, 127, 128, 129, 130, 131, 132); Protocol A; ambulance route = 11h amb_1 route (2 ambulances)
A2: Source: experiments/analysis/figures/main_comparison_02h_best10seeds_2026-09-30_en.json (same data as the PNG of that name); anomalous seeds (symmetric rule): none; Tukey outlier seeds: none
A4: Dublin 02:00, ambulance probe route, best checkpoints (8STD: exp287 ep770, GS-ENUM: exp288 ep760), 10 evaluation seeds
A5: Metric | B5: 8STD mean | C5: 8STD s.d. | D5: GS-ENUM mean | E5: GS-ENUM s.d. | F5: Rel. diff (GS-8STD)/8STD | G5: GS wins / paired | H5: Notes
A6: Stopped time / visit (s) - car | B6: 0.76431521 | C6: 0.058373169 | D6: 0.66105537 | E6: 0.051319888 | F6: =IF(B6=0,"",D6/B6-1) -> -0.13510112
A7: Stopped time / visit (s) - bus | B7: 0.39940476 | C7: 0.1761231 | D7: 0.3625 | E7: 0.18491606 | F7: =IF(B7=0,"",D7/B7-1) -> -0.092399404
A8: Stopped time / visit (s) - ambulance | B8: 0.375 | C8: 0.57282196 | D8: 0.25 | E8: 0.5 | F8: =IF(B8=0,"",D8/B8-1) -> -0.33333333 | H8: Few ambulances per evaluation in Dublin (02h: 2, 11h: 4, 18h: 1); do not cite the mean alone
A9: Stopped time / visit (s) - all | B9: 0.75991443 | C9: 0.056790125 | D9: 0.65731485 | E9: 0.050848917 | F9: =IF(B9=0,"",D9/B9-1) -> -0.13501466
A10: J(531) weighted cost (per visit) | B10: 0.77037753 | C10: 0.055236403 | D10: 0.66641035 | E10: 0.051891263 | F10: =IF(B10=0,"",D10/B10-1) -> -0.13495615 | G10: 9/10
A11: Ordering gate (stopped time): amb <= bus <= car | B11: =IF(AND(B8<=B7,B7<=B6),"pass",IF(AND(B8-B7<=5,B7-B6<=5),"pass (tol. 5 s)","fail")) -> pass | D11: =IF(AND(D8<=D7,D7<=D6),"pass",IF(AND(D8-D7<=5,D7-D6<=5),"pass (tol. 5 s)","fail")) -> pass | H11: tol. 5 s = tolerance of one 5 s sampling quantum
A12: Stop events / visit - car | B12: 0.10846498 | C12: 0.0074092542 | D12: 0.094655501 | E12: 0.0076080649 | F12: =IF(B12=0,"",D12/B12-1) -> -0.12731738
A13: Stop events / visit - bus | B13: 0.060238095 | C13: 0.022881931 | D13: 0.058928571 | E13: 0.028363579 | F13: =IF(B13=0,"",D13/B13-1) -> -0.02173913
A14: Stop events / visit - ambulance | B14: 0.075 | C14: 0.11456439 | D14: 0.05 | E14: 0.1 | F14: =IF(B14=0,"",D14/B14-1) -> -0.33333333 | H14: Few ambulances per evaluation in Dublin (02h: 2, 11h: 4, 18h: 1); do not cite the mean alone
A15: Stop events / visit - all | B15: 0.10791037 | C15: 0.0071788789 | D15: 0.094214654 | E15: 0.0074953253 | F15: =IF(B15=0,"",D15/B15-1) -> -0.12691755
A16: J(531) weighted stop events (per visit) | B16: 0.10957234 | C16: 0.0069339166 | D16: 0.095737134 | E16: 0.0075708906 | F16: =IF(B16=0,"",D16/B16-1) -> -0.12626548 | G16: 10/10
A17: Ordering gate (stop events): amb <= bus <= car (amb n/a: bus <= car only) | B17: =IF(B13<=B12,"pass (amb n/a)","fail (amb n/a)") -> pass (amb n/a) | D17: =IF(D13<=D12,"pass (amb n/a)","fail (amb n/a)") -> pass (amb n/a) | H17: 1-4 ambulances per evaluation: stop events take values 0 / 0.5 / 1 only, not comparable with the bus mean over hundreds of vehicles
A19: Dublin 02h: same route & departure time, ambulance vs bus probe, best checkpoints, 10 seeds
A20: Vehicle / metric | B20: seed 123 | C20: seed 124 | D20: seed 125 | E20: seed 126 | F20: seed 127 | G20: seed 128 | H20: seed 129 | I20: seed 130 | J20: seed 131 | K20: seed 132 | L20: Mean | M20: S.d.
A21: 8STD - ambulance (probe route) - Stopped time / visit (s) | B21: 1.25 | C21: 0 | D21: 1.25 | E21: 0 | F21: 0 | G21: 1.25 | H21: 0 | I21: 0 | J21: 0 | K21: 0 | L21: =AVERAGE(B21:K21) -> 0.375 | M21: =STDEV(B21:K21) -> 0.60380736
A22: 8STD - bus (same route & time) - Stopped time / visit (s) | B22: 8.75 | C22: 1.25 | D22: 1.25 | E22: 2.5 | F22: 1.25 | G22: 5 | H22: 1.25 | I22: 0 | J22: 0 | K22: 1.25 | L22: =AVERAGE(B22:K22) -> 2.25 | M22: =STDEV(B22:K22) -> 2.6874192
A23: 8STD - ambulance (probe route) - Stop events / visit | B23: 0.25 | C23: 0 | D23: 0.25 | E23: 0 | F23: 0 | G23: 0.25 | H23: 0 | I23: 0 | J23: 0 | K23: 0 | L23: =AVERAGE(B23:K23) -> 0.075 | M23: =STDEV(B23:K23) -> 0.12076147
A24: 8STD - bus (same route & time) - Stop events / visit | B24: 0.5 | C24: 0.25 | D24: 0.25 | E24: 0.25 | F24: 0.25 | G24: 0.5 | H24: 0.25 | I24: 0 | J24: 0 | K24: 0.25 | L24: =AVERAGE(B24:K24) -> 0.25 | M24: =STDEV(B24:K24) -> 0.16666667
A25: GS - ambulance (probe route) - Stopped time / visit (s) | B25: 1.25 | C25: 0 | D25: 0 | E25: 0 | F25: 0 | G25: 0 | H25: 0 | I25: 0 | J25: 0 | K25: 1.25 | L25: =AVERAGE(B25:K25) -> 0.25 | M25: =STDEV(B25:K25) -> 0.52704628
A26: GS - bus (same route & time) - Stopped time / visit (s) | B26: 1.25 | C26: 0 | D26: 1.25 | E26: 1.25 | F26: 0 | G26: 0 | H26: 1.25 | I26: 1.25 | J26: 1.25 | K26: 0 | L26: =AVERAGE(B26:K26) -> 0.75 | M26: =STDEV(B26:K26) -> 0.64549722
A27: GS - ambulance (probe route) - Stop events / visit | B27: 0.25 | C27: 0 | D27: 0 | E27: 0 | F27: 0 | G27: 0 | H27: 0 | I27: 0 | J27: 0 | K27: 0.25 | L27: =AVERAGE(B27:K27) -> 0.05 | M27: =STDEV(B27:K27) -> 0.10540926
A28: GS - bus (same route & time) - Stop events / visit | B28: 0.25 | C28: 0 | D28: 0.25 | E28: 0.25 | F28: 0 | G28: 0 | H28: 0.25 | I28: 0.25 | J28: 0.25 | K28: 0 | L28: =AVERAGE(B28:K28) -> 0.15 | M28: =STDEV(B28:K28) -> 0.12909944
A29: 8STD - stopped time: evaluations with ambulance < bus / ties | B29: =SUMPRODUCT(--(B21:K21<B22:K22))&" / "&SUMPRODUCT(--(B21:K21=B22:K22))&" (of 10)" -> 7 / 3 (of 10)
A30: 8STD - stop events: evaluations with ambulance < bus / ties | B30: =SUMPRODUCT(--(B23:K23<B24:K24))&" / "&SUMPRODUCT(--(B23:K23=B24:K24))&" (of 10)" -> 7 / 3 (of 10)
A31: GS - stopped time: evaluations with ambulance < bus / ties | B31: =SUMPRODUCT(--(B25:K25<B26:K26))&" / "&SUMPRODUCT(--(B25:K25=B26:K26))&" (of 10)" -> 5 / 4 (of 10)
A32: GS - stop events: evaluations with ambulance < bus / ties | B32: =SUMPRODUCT(--(B27:K27<B28:K28))&" / "&SUMPRODUCT(--(B27:K27=B28:K28))&" (of 10)" -> 5 / 4 (of 10)

Sheet Dublin 11h
A1: Dublin 11h: best checkpoints x 8 evaluation seeds (123, 124, 125, 126, 127, 129, 130, 131); Protocol A, USER-SELECTED: seeds 128 and 132 removed from both arms (8STD amb_0 caught at 389281 by Aungier St spillback, 45 s / 90 s)
A2: Source: experiments/analysis/figures/main_comparison_11h_best10seeds_SELECTED_excl128_132_2026-09-30_en.json (same data as the PNG of that name); anomalous seeds (symmetric rule): none; Tukey outlier seeds: none
A4: Dublin 11:00, best checkpoints x 8 seeds, seeds 128 & 132 removed (8STD: exp208 ep240, GS-ENUM: exp211 ep215) [USER-SELECTED]
A5: Metric | B5: 8STD mean | C5: 8STD s.d. | D5: GS-ENUM mean | E5: GS-ENUM s.d. | F5: Rel. diff (GS-8STD)/8STD | G5: GS wins / paired | H5: Notes
A6: Stopped time / visit (s) - car | B6: 2.7618967 | C6: 0.23672901 | D6: 2.0051525 | E6: 0.14814036 | F6: =IF(B6=0,"",D6/B6-1) -> -0.2739944
A7: Stopped time / visit (s) - bus | B7: 1.1040078 | C7: 0.10520985 | D7: 0.99663921 | E7: 0.055338254 | F7: =IF(B7=0,"",D7/B7-1) -> -0.097253447
A8: Stopped time / visit (s) - ambulance | B8: 0.9765625 | C8: 0.6123226 | D8: 0.8515625 | E8: 0.47898972 | F8: =IF(B8=0,"",D8/B8-1) -> -0.128 | H8: Few ambulances per evaluation in Dublin (02h: 2, 11h: 4, 18h: 1); do not cite the mean alone
A9: Stopped time / visit (s) - all | B9: 2.6792187 | C9: 0.22842508 | D9: 1.9546752 | E9: 0.14252837 | F9: =IF(B9=0,"",D9/B9-1) -> -0.27043091
A10: J(531) weighted cost (per visit) | B10: 2.7902746 | C10: 0.23578009 | D10: 2.0547157 | E10: 0.14643003 | F10: =IF(B10=0,"",D10/B10-1) -> -0.26361523 | G10: 8/8
A11: Ordering gate (stopped time): amb <= bus <= car | B11: =IF(AND(B8<=B7,B7<=B6),"pass",IF(AND(B8-B7<=5,B7-B6<=5),"pass (tol. 5 s)","fail")) -> pass | D11: =IF(AND(D8<=D7,D7<=D6),"pass",IF(AND(D8-D7<=5,D7-D6<=5),"pass (tol. 5 s)","fail")) -> pass | H11: tol. 5 s = tolerance of one 5 s sampling quantum
A12: Stop events / visit - car | B12: 0.3262034 | C12: 0.014264893 | D12: 0.24090684 | E12: 0.0080961472 | F12: =IF(B12=0,"",D12/B12-1) -> -0.26148274
A13: Stop events / visit - bus | B13: 0.1444686 | C13: 0.012117291 | D13: 0.14273686 | E13: 0.009854648 | F13: =IF(B13=0,"",D13/B13-1) -> -0.011986967
A14: Stop events / visit - ambulance | B14: 0.165625 | C14: 0.10657121 | D14: 0.134375 | E14: 0.065476021 | F14: =IF(B14=0,"",D14/B14-1) -> -0.18867925 | H14: Few ambulances per evaluation in Dublin (02h: 2, 11h: 4, 18h: 1); do not cite the mean alone
A15: Stop events / visit - all | B15: 0.31717422 | C15: 0.013771237 | D15: 0.23599889 | E15: 0.0079854083 | F15: =IF(B15=0,"",D15/B15-1) -> -0.25593293
A16: J(531) weighted stop events (per visit) | B16: 0.33180425 | C16: 0.014268494 | D16: 0.25033585 | E16: 0.0086540439 | F16: =IF(B16=0,"",D16/B16-1) -> -0.24553153 | G16: 8/8
A17: Ordering gate (stop events): amb <= bus <= car (amb n/a: bus <= car only) | B17: =IF(B13<=B12,"pass (amb n/a)","fail (amb n/a)") -> pass (amb n/a) | D17: =IF(D13<=D12,"pass (amb n/a)","fail (amb n/a)") -> pass (amb n/a) | H17: 1-4 ambulances per evaluation: stop events take values 0 / 0.5 / 1 only, not comparable with the bus mean over hundreds of vehicles
A19: Dublin 11:00: same route & departure time, ambulance vs bus probe, best checkpoints, 8 seeds [USER-SELECTED]
A20: Vehicle / metric | B20: seed 123 | C20: seed 124 | D20: seed 125 | E20: seed 126 | F20: seed 127 | G20: seed 129 | H20: seed 130 | I20: seed 131 | J20: Mean | K20: S.d.
A21: 8STD - ambulance (probe route) - Stopped time / visit (s) | B21: 2.5 | C21: 0 | D21: 5 | E21: 0 | F21: 2.5 | G21: 0 | H21: 0 | I21: 0 | J21: =AVERAGE(B21:I21) -> 1.25 | K21: =STDEV(B21:I21) -> 1.8898224
A22: 8STD - bus (same route & time) - Stopped time / visit (s) | B22: 2.5 | C22: 5 | D22: 0 | E22: 0 | F22: 0 | G22: 0 | H22: 2.5 | I22: 0 | J22: =AVERAGE(B22:I22) -> 1.25 | K22: =STDEV(B22:I22) -> 1.8898224
A23: 8STD - ambulance (probe route) - Stop events / visit | B23: 0.5 | C23: 0 | D23: 0.5 | E23: 0 | F23: 0.5 | G23: 0 | H23: 0 | I23: 0 | J23: =AVERAGE(B23:I23) -> 0.1875 | K23: =STDEV(B23:I23) -> 0.25877458
A24: 8STD - bus (same route & time) - Stop events / visit | B24: 0.5 | C24: 0.5 | D24: 0 | E24: 0 | F24: 0 | G24: 0 | H24: 0.5 | I24: 0 | J24: =AVERAGE(B24:I24) -> 0.1875 | K24: =STDEV(B24:I24) -> 0.25877458
A25: GS - ambulance (probe route) - Stopped time / visit (s) | B25: 0 | C25: 0 | D25: 0 | E25: 0 | F25: 0 | G25: 0 | H25: 2.5 | I25: 0 | J25: =AVERAGE(B25:I25) -> 0.3125 | K25: =STDEV(B25:I25) -> 0.88388348
A26: GS - bus (same route & time) - Stopped time / visit (s) | B26: 0 | C26: 0 | D26: 0 | E26: 0 | F26: 0 | G26: 0 | H26: 0 | I26: 2.5 | J26: =AVERAGE(B26:I26) -> 0.3125 | K26: =STDEV(B26:I26) -> 0.88388348
A27: GS - ambulance (probe route) - Stop events / visit | B27: 0 | C27: 0 | D27: 0 | E27: 0 | F27: 0 | G27: 0 | H27: 0.5 | I27: 0 | J27: =AVERAGE(B27:I27) -> 0.0625 | K27: =STDEV(B27:I27) -> 0.1767767
A28: GS - bus (same route & time) - Stop events / visit | B28: 0 | C28: 0 | D28: 0 | E28: 0 | F28: 0 | G28: 0 | H28: 0 | I28: 0.5 | J28: =AVERAGE(B28:I28) -> 0.0625 | K28: =STDEV(B28:I28) -> 0.1767767
A29: 8STD - stopped time: evaluations with ambulance < bus / ties | B29: =SUMPRODUCT(--(B21:I21<B22:I22))&" / "&SUMPRODUCT(--(B21:I21=B22:I22))&" (of 8)" -> 2 / 4 (of 8)
A30: 8STD - stop events: evaluations with ambulance < bus / ties | B30: =SUMPRODUCT(--(B23:I23<B24:I24))&" / "&SUMPRODUCT(--(B23:I23=B24:I24))&" (of 8)" -> 2 / 4 (of 8)
A31: GS - stopped time: evaluations with ambulance < bus / ties | B31: =SUMPRODUCT(--(B25:I25<B26:I26))&" / "&SUMPRODUCT(--(B25:I25=B26:I26))&" (of 8)" -> 1 / 6 (of 8)
A32: GS - stop events: evaluations with ambulance < bus / ties | B32: =SUMPRODUCT(--(B27:I27<B28:I28))&" / "&SUMPRODUCT(--(B27:I27=B28:I28))&" (of 8)" -> 1 / 6 (of 8)
A35: Dublin 11h: best checkpoints x 10 evaluation seeds (123, 124, 125, 126, 127, 128, 129, 130, 131, 132); Protocol A, all 10 seeds (reference)
A36: Source: experiments/analysis/figures/main_comparison_11h_best10seeds_2026-09-30_en.json (same data as the PNG of that name); anomalous seeds (symmetric rule): none; Tukey outlier seeds: none
A38: Dublin 11:00, best checkpoints x 10 seeds, all seeds (8STD: exp208 ep240, GS-ENUM: exp211 ep215) [reference]
A39: Metric | B39: 8STD mean | C39: 8STD s.d. | D39: GS-ENUM mean | E39: GS-ENUM s.d. | F39: Rel. diff (GS-8STD)/8STD | G39: GS wins / paired | H39: Notes
A40: Stopped time / visit (s) - car | B40: 2.7394267 | C40: 0.23817876 | D40: 1.9775838 | E40: 0.15141421 | F40: =IF(B40=0,"",D40/B40-1) -> -0.27810306
A41: Stopped time / visit (s) - bus | B41: 1.0914329 | C41: 0.097483067 | D41: 1.0061488 | E41: 0.053496785 | F41: =IF(B41=0,"",D41/B41-1) -> -0.078139587
A42: Stopped time / visit (s) - ambulance | B42: 1.6041667 | C42: 1.4705441 | D42: 0.78958333 | E42: 0.50753438 | F42: =IF(B42=0,"",D42/B42-1) -> -0.50779221 | H42: Few ambulances per evaluation in Dublin (02h: 2, 11h: 4, 18h: 1); do not cite the mean alone
A43: Stopped time / visit (s) - all | B43: 2.6578129 | C43: 0.22937321 | D43: 1.9288925 | E43: 0.14478997 | F43: =IF(B43=0,"",D43/B43-1) -> -0.27425573
A44: J(531) weighted cost (per visit) | B44: 2.7695931 | C44: 0.23586253 | D44: 2.0296419 | E44: 0.14694958 | F44: =IF(B44=0,"",D44/B44-1) -> -0.26716967 | G44: 10/10
A45: Ordering gate (stopped time): amb <= bus <= car | B45: =IF(AND(B42<=B41,B41<=B40),"pass",IF(AND(B42-B41<=5,B41-B40<=5),"pass (tol. 5 s)","fail")) -> pass (tol. 5 s) | D45: =IF(AND(D42<=D41,D41<=D40),"pass",IF(AND(D42-D41<=5,D41-D40<=5),"pass (tol. 5 s)","fail")) -> pass | H45: tol. 5 s = tolerance of one 5 s sampling quantum
...

Sheet Dublin 18h
A1: Dublin 18h: rerouted scenario v2 (177 cars/h leave at the Aungier approach end); GS arms on the split-slot enumerated net; SNAPSHOT (exp300 / exp301 still training)
A2: GS = exp300 (split-slot net, no other change); GS-2 = exp301 = exp300 + since-green observation + log-scale waiting + pressure-anchored phase score + TD-target floor -50. Best checkpoints frozen 2026-09-30 evening: 8STD exp298 ep200, GS exp300 ep145, GS-2 exp301 ep95.
A4: Dublin 18:00 rerouted v2, best checkpoints x 10 seeds, three arms [PRIMARY, snapshot]; seeds 123, 124, 125, 126, 127, 128, 129, 130, 131, 132; anomaly rule (any junction > 100 s in any arm): no hits
A5: Metric | B5: 8STD mean | C5: 8STD s.d. | D5: GS (exp300) mean | E5: GS (exp300) s.d. | F5: GS-2 (exp301) mean | G5: GS-2 (exp301) s.d. | H5: GS (exp300) vs 8STD | I5: GS-2 (exp301) vs 8STD | J5: GS-2 (exp301) vs GS (exp300) | K5: GS (exp300) wins vs 8STD | L5: GS-2 (exp301) wins vs 8STD | M5: Notes
A6: Stopped time / visit (s) - car | B6: 3.7300157 | C6: 0.10744 | D6: 5.9158701 | E6: 0.071332355 | F6: 3.1350181 | G6: 0.05606531 | H6: =IF(B6=0,"",D6/B6-1) -> 0.5860175 | I6: =IF(B6=0,"",F6/B6-1) -> -0.15951611 | J6: =IF(D6=0,"",F6/D6-1) -> -0.47006645 | K6: 0/10 (ties 0) | L6: 10/10 (ties 0)
A7: Stopped time / visit (s) - bus | B7: 1.1727486 | C7: 0.087606225 | D7: 1.1915138 | E7: 0.094737287 | F7: 1.4611542 | G7: 0.10935682 | H7: =IF(B7=0,"",D7/B7-1) -> 0.016001091 | I7: =IF(B7=0,"",F7/B7-1) -> 0.24592278 | J7: =IF(D7=0,"",F7/D7-1) -> 0.22630064 | K7: 5/10 (ties 0) | L7: 0/10 (ties 0)
A8: Stopped time / visit (s) - ambulance | B8: 1 | C8: 1.2247449 | D8: 4.75 | E8: 6.3688696 | F8: 0.75 | G8: 1.1456439 | H8: =IF(B8=0,"",D8/B8-1) -> 3.75 | I8: =IF(B8=0,"",F8/B8-1) -> -0.25 | J8: =IF(D8=0,"",F8/D8-1) -> -0.84210526 | K8: 1/10 (ties 5) | L8: 3/10 (ties 5) | M8: 1 ambulance per evaluation (probe route); do not cite the mean alone
A9: Stopped time / visit (s) - all | B9: 3.6038884 | C9: 0.10429949 | D9: 5.6830803 | E9: 0.067977987 | F9: 3.0521644 | G9: 0.055771747 | H9: =IF(B9=0,"",D9/B9-1) -> 0.57693015 | I9: =IF(B9=0,"",F9/B9-1) -> -0.1530913 | J9: =IF(D9=0,"",F9/D9-1) -> -0.46293835 | K9: 0/10 (ties 0) | L9: 10/10 (ties 0)
A10: J(531) weighted cost (per visit) | B10: 3.7211636 | C10: 0.10792797 | D10: 5.8187598 | E10: 0.070177809 | F10: 3.1888242 | G10: 0.060722661 | H10: =IF(B10=0,"",D10/B10-1) -> 0.56369365 | I10: =IF(B10=0,"",F10/B10-1) -> -0.14305724 | J10: =IF(D10=0,"",F10/D10-1) -> -0.45197529 | K10: 0/10 | L10: 10/10
A11: Ordering gate (stopped time): amb <= bus <= car | B11: =IF(AND(B8<=B7,B7<=B6),"pass",IF(AND(B8-B7<=5,B7-B6<=5),"pass (tol. 5 s)","fail")) -> pass | D11: =IF(AND(D8<=D7,D7<=D6),"pass",IF(AND(D8-D7<=5,D7-D6<=5),"pass (tol. 5 s)","fail")) -> pass (tol. 5 s) | F11: =IF(AND(F8<=F7,F7<=F6),"pass",IF(AND(F8-F7<=5,F7-F6<=5),"pass (tol. 5 s)","fail")) -> pass
A12: Stop events / visit - car | B12: 0.52544001 | C12: 0.016210036 | D12: 0.75011478 | E12: 0.013825445 | F12: 0.40684967 | G12: 0.0062643864 | H12: =IF(B12=0,"",D12/B12-1) -> 0.42759356 | I12: =IF(B12=0,"",F12/B12-1) -> -0.22569721 | J12: =IF(D12=0,"",F12/D12-1) -> -0.45761678 | K12: 0/10 (ties 0) | L12: 10/10 (ties 0)
A13: Stop events / visit - bus | B13: 0.18090628 | C13: 0.013026735 | D13: 0.17290118 | E13: 0.012688676 | F13: 0.22202772 | G13: 0.014864546 | H13: =IF(B13=0,"",D13/B13-1) -> -0.044250002 | I13: =IF(B13=0,"",F13/B13-1) -> 0.22730795 | J13: =IF(D13=0,"",F13/D13-1) -> 0.28413074 | K13: 8/10 (ties 0) | L13: 0/10 (ties 0)
A14: Stop events / visit - ambulance | B14: 0.2 | C14: 0.24494897 | D14: 0.2 | E14: 0.24494897 | F14: 0.15 | G14: 0.22912878 | H14: =IF(B14=0,"",D14/B14-1) -> 0 | I14: =IF(B14=0,"",F14/B14-1) -> -0.25 | J14: =IF(D14=0,"",F14/D14-1) -> -0.25 | K14: 1/10 (ties 8) | L14: 3/10 (ties 5) | M14: 1 ambulance per evaluation (probe route); do not cite the mean alone
A15: Stop events / visit - all | B15: 0.50845655 | C15: 0.015638021 | D15: 0.72158541 | E15: 0.01321657 | F15: 0.39770224 | G15: 0.0063698352 | H15: =IF(B15=0,"",D15/B15-1) -> 0.41916829 | I15: =IF(B15=0,"",F15/B15-1) -> -0.21782453 | J15: =IF(D15=0,"",F15/D15-1) -> -0.44884939 | K15: 0/10 (ties 0) | L15: 10/10 (ties 0)
A16: J(531) weighted stop events (per visit) | B16: 0.52627791 | C16: 0.016012981 | D16: 0.74021407 | E16: 0.013616689 | F16: 0.41806534 | G16: 0.0072129497 | H16: =IF(B16=0,"",D16/B16-1) -> 0.40650795 | I16: =IF(B16=0,"",F16/B16-1) -> -0.20561869 | J16: =IF(D16=0,"",F16/D16-1) -> -0.43521023 | K16: 0/10 | L16: 10/10
A17: Ordering gate (stop events): amb <= bus <= car (amb n/a: bus <= car only) | B17: =IF(B13<=B12,"pass (amb n/a)","fail (amb n/a)") -> pass (amb n/a) | D17: =IF(D13<=D12,"pass (amb n/a)","fail (amb n/a)") -> pass (amb n/a) | F17: =IF(F13<=F12,"pass (amb n/a)","fail (amb n/a)") -> pass (amb n/a)
A19: Dublin 18:00 rerouted v2, best checkpoints x 10 seeds, three arms [PRIMARY, snapshot]: same route & departure time, ambulance vs bus probe, 10 seeds
A20: Vehicle / metric | B20: seed 123 | C20: seed 124 | D20: seed 125 | E20: seed 126 | F20: seed 127 | G20: seed 128 | H20: seed 129 | I20: seed 130 | J20: seed 131 | K20: seed 132 | L20: Mean | M20: S.d.
A21: 8STD - ambulance (probe route) - Stopped time / visit (s) | B21: 0 | C21: 0 | D21: 2.5 | E21: 0 | F21: 2.5 | G21: 0 | H21: 2.5 | I21: 2.5 | J21: 0 | K21: 0 | L21: =AVERAGE(B21:K21) -> 1 | M21: =STDEV(B21:K21) -> 1.2909944
A22: 8STD - bus (same route & time) - Stopped time / visit (s) | B22: 0 | C22: 2.5 | D22: 5 | E22: 0 | F22: 5 | G22: 2.5 | H22: 5 | I22: 5 | J22: 2.5 | K22: 2.5 | L22: =AVERAGE(B22:K22) -> 3 | M22: =STDEV(B22:K22) -> 1.9720266
A23: 8STD - ambulance (probe route) - Stop events / visit | B23: 0 | C23: 0 | D23: 0.5 | E23: 0 | F23: 0.5 | G23: 0 | H23: 0.5 | I23: 0.5 | J23: 0 | K23: 0 | L23: =AVERAGE(B23:K23) -> 0.2 | M23: =STDEV(B23:K23) -> 0.25819889
A24: 8STD - bus (same route & time) - Stop events / visit | B24: 0 | C24: 0.5 | D24: 0.5 | E24: 0 | F24: 0.5 | G24: 0.5 | H24: 0.5 | I24: 0.5 | J24: 0.5 | K24: 0.5 | L24: =AVERAGE(B24:K24) -> 0.4 | M24: =STDEV(B24:K24) -> 0.21081851
A25: GS (exp300) - ambulance (probe route) - Stopped time / visit (s) | B25: 0 | C25: 15 | D25: 0 | E25: 0 | F25: 12.5 | G25: 0 | H25: 15 | I25: 5 | J25: 0 | K25: 0 | L25: =AVERAGE(B25:K25) -> 4.75 | M25: =STDEV(B25:K25) -> 6.713378
A26: GS (exp300) - bus (same route & time) - Stopped time / visit (s) | B26: 0 | C26: 0 | D26: 0 | E26: 0 | F26: 0 | G26: 0 | H26: 0 | I26: 0 | J26: 0 | K26: 0 | L26: =AVERAGE(B26:K26) -> 0 | M26: =STDEV(B26:K26) -> 0
A27: GS (exp300) - ambulance (probe route) - Stop events / visit | B27: 0 | C27: 0.5 | D27: 0 | E27: 0 | F27: 0.5 | G27: 0 | H27: 0.5 | I27: 0.5 | J27: 0 | K27: 0 | L27: =AVERAGE(B27:K27) -> 0.2 | M27: =STDEV(B27:K27) -> 0.25819889
A28: GS (exp300) - bus (same route & time) - Stop events / visit | B28: 0 | C28: 0 | D28: 0 | E28: 0 | F28: 0 | G28: 0 | H28: 0 | I28: 0 | J28: 0 | K28: 0 | L28: =AVERAGE(B28:K28) -> 0 | M28: =STDEV(B28:K28) -> 0
A29: GS-2 (exp301) - ambulance (probe route) - Stopped time / visit (s) | B29: 2.5 | C29: 0 | D29: 0 | E29: 0 | F29: 2.5 | G29: 0 | H29: 0 | I29: 0 | J29: 2.5 | K29: 0 | L29: =AVERAGE(B29:K29) -> 0.75 | M29: =STDEV(B29:K29) -> 1.2076147
A30: GS-2 (exp301) - bus (same route & time) - Stopped time / visit (s) | B30: 0 | C30: 0 | D30: 0 | E30: 0 | F30: 0 | G30: 2.5 | H30: 0 | I30: 0 | J30: 0 | K30: 0 | L30: =AVERAGE(B30:K30) -> 0.25 | M30: =STDEV(B30:K30) -> 0.79056942
A31: GS-2 (exp301) - ambulance (probe route) - Stop events / visit | B31: 0.5 | C31: 0 | D31: 0 | E31: 0 | F31: 0.5 | G31: 0 | H31: 0 | I31: 0 | J31: 0.5 | K31: 0 | L31: =AVERAGE(B31:K31) -> 0.15 | M31: =STDEV(B31:K31) -> 0.24152295
A32: GS-2 (exp301) - bus (same route & time) - Stop events / visit | B32: 0 | C32: 0 | D32: 0 | E32: 0 | F32: 0 | G32: 0.5 | H32: 0 | I32: 0 | J32: 0 | K32: 0 | L32: =AVERAGE(B32:K32) -> 0.05 | M32: =STDEV(B32:K32) -> 0.15811388
A33: 8STD - stopped time: evaluations with ambulance < bus / ties | B33: =SUMPRODUCT(--(B21:K21<B22:K22))&" / "&SUMPRODUCT(--(B21:K21=B22:K22))&" (of 10)" -> 8 / 2 (of 10)
A34: 8STD - stop events: evaluations with ambulance < bus / ties | B34: =SUMPRODUCT(--(B23:K23<B24:K24))&" / "&SUMPRODUCT(--(B23:K23=B24:K24))&" (of 10)" -> 4 / 6 (of 10)
A35: GS (exp300) - stopped time: evaluations with ambulance < bus / ties | B35: =SUMPRODUCT(--(B25:K25<B26:K26))&" / "&SUMPRODUCT(--(B25:K25=B26:K26))&" (of 10)" -> 0 / 6 (of 10)
A36: GS (exp300) - stop events: evaluations with ambulance < bus / ties | B36: =SUMPRODUCT(--(B27:K27<B28:K28))&" / "&SUMPRODUCT(--(B27:K27=B28:K28))&" (of 10)" -> 0 / 6 (of 10)
A37: GS-2 (exp301) - stopped time: evaluations with ambulance < bus / ties | B37: =SUMPRODUCT(--(B29:K29<B30:K30))&" / "&SUMPRODUCT(--(B29:K29=B30:K30))&" (of 10)" -> 1 / 6 (of 10)
A38: GS-2 (exp301) - stop events: evaluations with ambulance < bus / ties | B38: =SUMPRODUCT(--(B31:K31<B32:K32))&" / "&SUMPRODUCT(--(B31:K31=B32:K32))&" (of 10)" -> 1 / 6 (of 10)
A41: Dublin 18h: best checkpoints x 10 evaluation seeds (123, 124, 125, 126, 127, 128, 129, 130, 131, 132); Protocol A; rerouted scenario v2 (Aungier right-turn cars leave at the approach end), GS on the split-slot enumerated net; SNAPSHOT: exp300 still training
A42: Source: experiments/analysis/figures/main_comparison_18h_best10seeds_reroute_v2_2026-09-30_en.json (same data as the PNG of that name); anomalous seeds (symmetric rule): none; Tukey outlier seeds: none
A44: Dublin 18:00, rerouted scenario v2, best checkpoints x 10 seeds, two arms (8STD: exp298 ep200, GS-ENUM: exp300 ep145); anomaly rule (>100 s): no hits [reference: same data as the PNG]
A45: Metric | B45: 8STD mean | C45: 8STD s.d. | D45: GS-ENUM mean | E45: GS-ENUM s.d. | F45: Rel. diff (GS-8STD)/8STD | G45: GS wins / paired | H45: Notes
...
